[2022-08-01 10:57:22,512] {taskinstance.py:1179} INFO - Dependencies all met for <TaskInstance: Demo.container_creation manual__2022-08-01T10:57:18.813861+00:00 [queued]>
[2022-08-01 10:57:22,534] {taskinstance.py:1179} INFO - Dependencies all met for <TaskInstance: Demo.container_creation manual__2022-08-01T10:57:18.813861+00:00 [queued]>
[2022-08-01 10:57:22,535] {taskinstance.py:1376} INFO - 
--------------------------------------------------------------------------------
[2022-08-01 10:57:22,536] {taskinstance.py:1377} INFO - Starting attempt 1 of 1
[2022-08-01 10:57:22,538] {taskinstance.py:1378} INFO - 
--------------------------------------------------------------------------------
[2022-08-01 10:57:22,574] {taskinstance.py:1397} INFO - Executing <Task(PythonOperator): container_creation> on 2022-08-01 10:57:18.813861+00:00
[2022-08-01 10:57:22,582] {standard_task_runner.py:52} INFO - Started process 1995 to run task
[2022-08-01 10:57:22,589] {standard_task_runner.py:79} INFO - Running: ['***', 'tasks', 'run', 'Demo', 'container_creation', 'manual__2022-08-01T10:57:18.813861+00:00', '--job-id', '66', '--raw', '--subdir', 'DAGS_FOLDER/demo.py', '--cfg-path', '/tmp/tmph94we706', '--error-file', '/tmp/tmprmn2gctq']
[2022-08-01 10:57:22,590] {standard_task_runner.py:80} INFO - Job 66: Subtask container_creation
[2022-08-01 10:57:22,835] {task_command.py:371} INFO - Running <TaskInstance: Demo.container_creation manual__2022-08-01T10:57:18.813861+00:00 [running]> on host 31353b71d6cb
[2022-08-01 10:57:23,122] {taskinstance.py:1591} INFO - Exporting the following env vars:
AIRFLOW_CTX_DAG_OWNER=***
AIRFLOW_CTX_DAG_ID=Demo
AIRFLOW_CTX_TASK_ID=container_creation
AIRFLOW_CTX_EXECUTION_DATE=2022-08-01T10:57:18.813861+00:00
AIRFLOW_CTX_TRY_NUMBER=1
AIRFLOW_CTX_DAG_RUN_ID=manual__2022-08-01T10:57:18.813861+00:00
[2022-08-01 10:57:23,125] {taskinstance.py:1909} ERROR - Task failed with exception
Traceback (most recent call last):
  File "/home/airflow/.local/lib/python3.7/site-packages/airflow/operators/python.py", line 171, in execute
    return_value = self.execute_callable()
  File "/home/airflow/.local/lib/python3.7/site-packages/airflow/operators/python.py", line 189, in execute_callable
    return self.python_callable(*self.op_args, **self.op_kwargs)
  File "/opt/airflow/dags/demo.py", line 12, in create_container
    waves_dict_ids,transcriptions_dict_ids=API_Call_Result()
  File "/opt/airflow/dags/external_files/confidential_client_secret_sample.py", line 52, in API_Call_Result
    if not result:
UnboundLocalError: local variable 'result' referenced before assignment
[2022-08-01 10:57:23,169] {taskinstance.py:1420} INFO - Marking task as FAILED. dag_id=Demo, task_id=container_creation, execution_date=20220801T105718, start_date=20220801T105722, end_date=20220801T105723
[2022-08-01 10:57:23,222] {standard_task_runner.py:97} ERROR - Failed to execute job 66 for task container_creation (local variable 'result' referenced before assignment; 1995)
[2022-08-01 10:57:23,245] {local_task_job.py:156} INFO - Task exited with return code 1
[2022-08-01 10:57:23,369] {local_task_job.py:273} INFO - 0 downstream tasks scheduled from follow-on schedule check
