[2022-07-27 14:34:36,306] {taskinstance.py:1179} INFO - Dependencies all met for <TaskInstance: Demo.data_uploading manual__2022-07-27T14:32:20.774651+00:00 [queued]>
[2022-07-27 14:34:36,324] {taskinstance.py:1179} INFO - Dependencies all met for <TaskInstance: Demo.data_uploading manual__2022-07-27T14:32:20.774651+00:00 [queued]>
[2022-07-27 14:34:36,324] {taskinstance.py:1376} INFO - 
--------------------------------------------------------------------------------
[2022-07-27 14:34:36,325] {taskinstance.py:1377} INFO - Starting attempt 1 of 1
[2022-07-27 14:34:36,325] {taskinstance.py:1378} INFO - 
--------------------------------------------------------------------------------
[2022-07-27 14:34:36,413] {taskinstance.py:1397} INFO - Executing <Task(PythonOperator): data_uploading> on 2022-07-27 14:32:20.774651+00:00
[2022-07-27 14:34:36,418] {standard_task_runner.py:52} INFO - Started process 1058 to run task
[2022-07-27 14:34:36,423] {standard_task_runner.py:79} INFO - Running: ['***', 'tasks', 'run', 'Demo', 'data_uploading', 'manual__2022-07-27T14:32:20.774651+00:00', '--job-id', '8', '--raw', '--subdir', 'DAGS_FOLDER/demo.py', '--cfg-path', '/tmp/tmph986bw99', '--error-file', '/tmp/tmpx0rlcvml']
[2022-07-27 14:34:36,423] {standard_task_runner.py:80} INFO - Job 8: Subtask data_uploading
[2022-07-27 14:34:36,564] {task_command.py:371} INFO - Running <TaskInstance: Demo.data_uploading manual__2022-07-27T14:32:20.774651+00:00 [running]> on host fafad4d69e23
[2022-07-27 14:34:36,773] {taskinstance.py:1591} INFO - Exporting the following env vars:
AIRFLOW_CTX_DAG_OWNER=***
AIRFLOW_CTX_DAG_ID=Demo
AIRFLOW_CTX_TASK_ID=data_uploading
AIRFLOW_CTX_EXECUTION_DATE=2022-07-27T14:32:20.774651+00:00
AIRFLOW_CTX_TRY_NUMBER=1
AIRFLOW_CTX_DAG_RUN_ID=manual__2022-07-27T14:32:20.774651+00:00
[2022-07-27 14:34:36,788] {base.py:68} INFO - Using connection ID 'demo' for task execution.
[2022-07-27 14:34:36,791] {taskinstance.py:1909} ERROR - Task failed with exception
Traceback (most recent call last):
  File "/home/airflow/.local/lib/python3.7/site-packages/airflow/operators/python.py", line 171, in execute
    return_value = self.execute_callable()
  File "/home/airflow/.local/lib/python3.7/site-packages/airflow/operators/python.py", line 189, in execute_callable
    return self.python_callable(*self.op_args, **self.op_kwargs)
  File "/opt/airflow/dags/demo.py", line 21, in upload_data
    test.load_file(file_path="/opt/airflow/files/example_2.json",container_name="demo",blob_name="example")
  File "/home/airflow/.local/lib/python3.7/site-packages/airflow/providers/microsoft/azure/hooks/wasb.py", line 255, in load_file
    with open(file_path, 'rb') as data:
FileNotFoundError: [Errno 2] No such file or directory: '/opt/airflow/files/example_2.json'
[2022-07-27 14:34:36,806] {taskinstance.py:1420} INFO - Marking task as FAILED. dag_id=Demo, task_id=data_uploading, execution_date=20220727T143220, start_date=20220727T143436, end_date=20220727T143436
[2022-07-27 14:34:36,880] {standard_task_runner.py:97} ERROR - Failed to execute job 8 for task data_uploading ([Errno 2] No such file or directory: '/opt/airflow/files/example_2.json'; 1058)
[2022-07-27 14:34:36,959] {local_task_job.py:156} INFO - Task exited with return code 1
[2022-07-27 14:34:37,047] {local_task_job.py:273} INFO - 0 downstream tasks scheduled from follow-on schedule check
