[2022-07-13 00:56:53,634] {taskinstance.py:1159} INFO - Dependencies all met for <TaskInstance: Demo.demo manual__2022-07-13T00:56:48.347488+00:00 [queued]>
[2022-07-13 00:56:53,721] {taskinstance.py:1159} INFO - Dependencies all met for <TaskInstance: Demo.demo manual__2022-07-13T00:56:48.347488+00:00 [queued]>
[2022-07-13 00:56:53,723] {taskinstance.py:1356} INFO - 
--------------------------------------------------------------------------------
[2022-07-13 00:56:53,727] {taskinstance.py:1357} INFO - Starting attempt 1 of 1
[2022-07-13 00:56:53,728] {taskinstance.py:1358} INFO - 
--------------------------------------------------------------------------------
[2022-07-13 00:56:55,687] {taskinstance.py:1377} INFO - Executing <Task(PythonOperator): demo> on 2022-07-13 00:56:48.347488+00:00
[2022-07-13 00:56:55,702] {standard_task_runner.py:52} INFO - Started process 1029 to run task
[2022-07-13 00:56:55,721] {standard_task_runner.py:79} INFO - Running: ['***', 'tasks', 'run', 'Demo', 'demo', 'manual__2022-07-13T00:56:48.347488+00:00', '--job-id', '23', '--raw', '--subdir', 'DAGS_FOLDER/demo.py', '--cfg-path', '/tmp/tmp07jdslk_', '--error-file', '/tmp/tmpx_gozbbx']
[2022-07-13 00:56:55,723] {standard_task_runner.py:80} INFO - Job 23: Subtask demo
[2022-07-13 00:56:56,268] {task_command.py:370} INFO - Running <TaskInstance: Demo.demo manual__2022-07-13T00:56:48.347488+00:00 [running]> on host 939e047cba2c
[2022-07-13 00:57:01,197] {taskinstance.py:1571} INFO - Exporting the following env vars:
AIRFLOW_CTX_DAG_OWNER=***
AIRFLOW_CTX_DAG_ID=Demo
AIRFLOW_CTX_TASK_ID=demo
AIRFLOW_CTX_EXECUTION_DATE=2022-07-13T00:56:48.347488+00:00
AIRFLOW_CTX_TRY_NUMBER=1
AIRFLOW_CTX_DAG_RUN_ID=manual__2022-07-13T00:56:48.347488+00:00
[2022-07-13 00:57:01,251] {base.py:68} INFO - Using connection ID 'demo' for task execution.
[2022-07-13 00:57:01,263] {logging_mixin.py:115} INFO - <***.providers.microsoft.azure.hooks.wasb.WasbHook object at 0x7f9cc91eeb50>
[2022-07-13 00:57:01,265] {logging_mixin.py:115} INFO - connection made successfully
[2022-07-13 00:57:01,277] {_universal.py:476} INFO - Request URL: 'http://azurite:10000/devstoreaccount1/demo?restype=REDACTED&comp=REDACTED&delimiter=REDACTED'
Request method: 'GET'
Request headers:
    'x-ms-version': 'REDACTED'
    'Accept': 'application/xml'
    'User-Agent': 'azsdk-python-storage-blob/12.8.1 Python/3.7.13 (Linux-5.10.16.3-microsoft-standard-WSL2-x86_64-with-debian-11.3)'
    'x-ms-date': 'REDACTED'
    'x-ms-client-request-id': 'b43560b0-0246-11ed-b81d-0242ac120006'
    'Authorization': 'REDACTED'
No body was attached to the request
[2022-07-13 00:57:01,387] {_universal.py:504} INFO - Response status: 404
Response headers:
    'Server': 'Azurite-Blob/3.18.0'
    'x-ms-error-code': 'REDACTED'
    'x-ms-request-id': 'a0dc9250-3748-4872-8210-c2ac111226ed'
    'content-type': 'application/xml'
    'Date': 'Wed, 13 Jul 2022 00:57:01 GMT'
    'Connection': 'keep-alive'
    'Keep-Alive': 'REDACTED'
    'Transfer-Encoding': 'chunked'
[2022-07-13 00:57:01,394] {taskinstance.py:1889} ERROR - Task failed with exception
Traceback (most recent call last):
  File "/home/airflow/.local/lib/python3.7/site-packages/azure/storage/blob/_list_blobs_helper.py", line 77, in _get_next_cb
    use_location=self.location_mode)
  File "/home/airflow/.local/lib/python3.7/site-packages/azure/storage/blob/_generated/operations/_container_operations.py", line 1576, in list_blob_hierarchy_segment
    map_error(status_code=response.status_code, response=response, error_map=error_map)
  File "/home/airflow/.local/lib/python3.7/site-packages/azure/core/exceptions.py", line 107, in map_error
    raise error
azure.core.exceptions.ResourceNotFoundError: Operation returned an invalid status 'The specified container does not exist.'
Content: <?xml version="1.0" encoding="UTF-8" standalone="yes"?>
<Error>
  <Code>ContainerNotFound</Code>
  <Message>The specified container does not exist.
RequestId:a0dc9250-3748-4872-8210-c2ac111226ed
Time:2022-07-13T00:57:01.379Z</Message>
</Error>

During handling of the above exception, another exception occurred:

Traceback (most recent call last):
  File "/home/airflow/.local/lib/python3.7/site-packages/airflow/operators/python.py", line 171, in execute
    return_value = self.execute_callable()
  File "/home/airflow/.local/lib/python3.7/site-packages/airflow/operators/python.py", line 189, in execute_callable
    return self.python_callable(*self.op_args, **self.op_kwargs)
  File "/opt/airflow/dags/demo.py", line 12, in demo
    x=test.get_blobs_list(container_name="demo")
  File "/home/airflow/.local/lib/python3.7/site-packages/airflow/providers/microsoft/azure/hooks/wasb.py", line 231, in get_blobs_list
    for blob in blobs:
  File "/home/airflow/.local/lib/python3.7/site-packages/azure/core/paging.py", line 129, in __next__
    return next(self._page_iterator)
  File "/home/airflow/.local/lib/python3.7/site-packages/azure/core/paging.py", line 76, in __next__
    self._response = self._get_next(self.continuation_token)
  File "/home/airflow/.local/lib/python3.7/site-packages/azure/storage/blob/_list_blobs_helper.py", line 79, in _get_next_cb
    process_storage_error(error)
  File "/home/airflow/.local/lib/python3.7/site-packages/azure/storage/blob/_shared/response_handlers.py", line 150, in process_storage_error
    error.raise_with_traceback()
  File "/home/airflow/.local/lib/python3.7/site-packages/azure/core/exceptions.py", line 249, in raise_with_traceback
    raise super(AzureError, self).with_traceback(self.exc_traceback)
  File "/home/airflow/.local/lib/python3.7/site-packages/azure/storage/blob/_list_blobs_helper.py", line 77, in _get_next_cb
    use_location=self.location_mode)
  File "/home/airflow/.local/lib/python3.7/site-packages/azure/storage/blob/_generated/operations/_container_operations.py", line 1576, in list_blob_hierarchy_segment
    map_error(status_code=response.status_code, response=response, error_map=error_map)
  File "/home/airflow/.local/lib/python3.7/site-packages/azure/core/exceptions.py", line 107, in map_error
    raise error
azure.core.exceptions.ResourceNotFoundError: The specified container does not exist.
RequestId:a0dc9250-3748-4872-8210-c2ac111226ed
Time:2022-07-13T00:57:01.379Z
ErrorCode:ContainerNotFound
Error:
  
Content: <?xml version="1.0" encoding="UTF-8" standalone="yes"?>
<Error>
  <Code>ContainerNotFound</Code>
  <Message>The specified container does not exist.
RequestId:a0dc9250-3748-4872-8210-c2ac111226ed
Time:2022-07-13T00:57:01.379Z</Message>
</Error>
[2022-07-13 00:57:01,523] {taskinstance.py:1400} INFO - Marking task as FAILED. dag_id=Demo, task_id=demo, execution_date=20220713T005648, start_date=20220713T005653, end_date=20220713T005701
[2022-07-13 00:57:01,768] {standard_task_runner.py:97} ERROR - Failed to execute job 23 for task demo (The specified container does not exist.
RequestId:a0dc9250-3748-4872-8210-c2ac111226ed
Time:2022-07-13T00:57:01.379Z
ErrorCode:ContainerNotFound
Error:
  
Content: <?xml version="1.0" encoding="UTF-8" standalone="yes"?>
<Error>
  <Code>ContainerNotFound</Code>
  <Message>The specified container does not exist.
RequestId:a0dc9250-3748-4872-8210-c2ac111226ed
Time:2022-07-13T00:57:01.379Z</Message>
</Error>; 1029)
[2022-07-13 00:57:01,809] {local_task_job.py:156} INFO - Task exited with return code 1
[2022-07-13 00:57:02,090] {local_task_job.py:273} INFO - 0 downstream tasks scheduled from follow-on schedule check
