[2022-08-02 10:13:34,660] {taskinstance.py:1179} INFO - Dependencies all met for <TaskInstance: Demo.records_saving manual__2022-08-02T10:13:08.032832+00:00 [queued]>
[2022-08-02 10:13:34,752] {taskinstance.py:1179} INFO - Dependencies all met for <TaskInstance: Demo.records_saving manual__2022-08-02T10:13:08.032832+00:00 [queued]>
[2022-08-02 10:13:34,755] {taskinstance.py:1376} INFO - 
--------------------------------------------------------------------------------
[2022-08-02 10:13:34,756] {taskinstance.py:1377} INFO - Starting attempt 1 of 1
[2022-08-02 10:13:34,757] {taskinstance.py:1378} INFO - 
--------------------------------------------------------------------------------
[2022-08-02 10:13:34,839] {taskinstance.py:1397} INFO - Executing <Task(PythonOperator): records_saving> on 2022-08-02 10:13:08.032832+00:00
[2022-08-02 10:13:34,919] {standard_task_runner.py:52} INFO - Started process 4593 to run task
[2022-08-02 10:13:34,942] {standard_task_runner.py:79} INFO - Running: ['***', 'tasks', 'run', 'Demo', 'records_saving', 'manual__2022-08-02T10:13:08.032832+00:00', '--job-id', '215', '--raw', '--subdir', 'DAGS_FOLDER/demo.py', '--cfg-path', '/tmp/tmpqc5m14qn', '--error-file', '/tmp/tmpizz_bec7']
[2022-08-02 10:13:34,945] {standard_task_runner.py:80} INFO - Job 215: Subtask records_saving
[2022-08-02 10:13:35,404] {task_command.py:371} INFO - Running <TaskInstance: Demo.records_saving manual__2022-08-02T10:13:08.032832+00:00 [running]> on host 31353b71d6cb
[2022-08-02 10:13:35,867] {taskinstance.py:1591} INFO - Exporting the following env vars:
AIRFLOW_CTX_DAG_OWNER=***
AIRFLOW_CTX_DAG_ID=Demo
AIRFLOW_CTX_TASK_ID=records_saving
AIRFLOW_CTX_EXECUTION_DATE=2022-08-02T10:13:08.032832+00:00
AIRFLOW_CTX_TRY_NUMBER=1
AIRFLOW_CTX_DAG_RUN_ID=manual__2022-08-02T10:13:08.032832+00:00
[2022-08-02 10:13:35,945] {base.py:68} INFO - Using connection ID 'postgres_demo' for task execution.
[2022-08-02 10:13:35,996] {dbapi.py:231} INFO - Running statement: CREATE TABLE IF NOT EXISTS public."Files"
                            (
                                id integer NOT NULL,
                                name character(80)[] COLLATE pg_catalog."default" NOT NULL,
                                size bigint,
                                CONSTRAINT "Files_pkey" PRIMARY KEY (id)
                            ), parameters: None
[2022-08-02 10:13:36,002] {taskinstance.py:1909} ERROR - Task failed with exception
Traceback (most recent call last):
  File "/home/airflow/.local/lib/python3.7/site-packages/airflow/operators/python.py", line 171, in execute
    return_value = self.execute_callable()
  File "/home/airflow/.local/lib/python3.7/site-packages/airflow/operators/python.py", line 189, in execute_callable
    return self.python_callable(*self.op_args, **self.op_kwargs)
  File "/opt/airflow/dags/demo.py", line 62, in save_records
    VALUES (%(params.id)s, %(params.name)s, %(params.size)s);""",params={"id":i,"name":"houssem","size":i+100})
TypeError: run() got an unexpected keyword argument 'params'
[2022-08-02 10:13:36,133] {taskinstance.py:1420} INFO - Marking task as FAILED. dag_id=Demo, task_id=records_saving, execution_date=20220802T101308, start_date=20220802T101334, end_date=20220802T101336
[2022-08-02 10:13:36,232] {standard_task_runner.py:97} ERROR - Failed to execute job 215 for task records_saving (run() got an unexpected keyword argument 'params'; 4593)
[2022-08-02 10:13:36,303] {local_task_job.py:156} INFO - Task exited with return code 1
[2022-08-02 10:13:36,508] {local_task_job.py:273} INFO - 0 downstream tasks scheduled from follow-on schedule check
