[2022-08-02 13:03:29,885] {taskinstance.py:1179} INFO - Dependencies all met for <TaskInstance: Demo.data_uploading_mongodb manual__2022-08-02T13:03:08.564821+00:00 [queued]>
[2022-08-02 13:03:29,897] {taskinstance.py:1179} INFO - Dependencies all met for <TaskInstance: Demo.data_uploading_mongodb manual__2022-08-02T13:03:08.564821+00:00 [queued]>
[2022-08-02 13:03:29,897] {taskinstance.py:1376} INFO - 
--------------------------------------------------------------------------------
[2022-08-02 13:03:29,898] {taskinstance.py:1377} INFO - Starting attempt 1 of 1
[2022-08-02 13:03:29,898] {taskinstance.py:1378} INFO - 
--------------------------------------------------------------------------------
[2022-08-02 13:03:29,915] {taskinstance.py:1397} INFO - Executing <Task(PythonOperator): data_uploading_mongodb> on 2022-08-02 13:03:08.564821+00:00
[2022-08-02 13:03:29,919] {standard_task_runner.py:52} INFO - Started process 10587 to run task
[2022-08-02 13:03:29,922] {standard_task_runner.py:79} INFO - Running: ['***', 'tasks', 'run', 'Demo', 'data_uploading_mongodb', 'manual__2022-08-02T13:03:08.564821+00:00', '--job-id', '297', '--raw', '--subdir', 'DAGS_FOLDER/demo.py', '--cfg-path', '/tmp/tmp8247_ont', '--error-file', '/tmp/tmpkat004o0']
[2022-08-02 13:03:29,923] {standard_task_runner.py:80} INFO - Job 297: Subtask data_uploading_mongodb
[2022-08-02 13:03:30,001] {task_command.py:371} INFO - Running <TaskInstance: Demo.data_uploading_mongodb manual__2022-08-02T13:03:08.564821+00:00 [running]> on host 31353b71d6cb
[2022-08-02 13:03:30,091] {taskinstance.py:1591} INFO - Exporting the following env vars:
AIRFLOW_CTX_DAG_OWNER=***
AIRFLOW_CTX_DAG_ID=Demo
AIRFLOW_CTX_TASK_ID=data_uploading_mongodb
AIRFLOW_CTX_EXECUTION_DATE=2022-08-02T13:03:08.564821+00:00
AIRFLOW_CTX_TRY_NUMBER=1
AIRFLOW_CTX_DAG_RUN_ID=manual__2022-08-02T13:03:08.564821+00:00
[2022-08-02 13:03:30,103] {base.py:68} INFO - Using connection ID 'azure_demo' for task execution.
[2022-08-02 13:03:30,109] {_universal.py:476} INFO - Request URL: 'http://azurite:10000/devstoreaccount1/transcriptions/file_1'
Request method: 'GET'
Request headers:
    'x-ms-range': 'REDACTED'
    'x-ms-version': 'REDACTED'
    'Accept': 'application/xml'
    'User-Agent': 'azsdk-python-storage-blob/12.8.1 Python/3.7.13 (Linux-5.10.16.3-microsoft-standard-WSL2-x86_64-with-debian-11.4)'
    'x-ms-date': 'REDACTED'
    'x-ms-client-request-id': '8170fafe-1263-11ed-96b6-0242ac120007'
    'Authorization': 'REDACTED'
No body was attached to the request
[2022-08-02 13:03:30,155] {_universal.py:504} INFO - Response status: 206
Response headers:
    'Server': 'Azurite-Blob/3.18.0'
    'last-modified': 'Tue, 02 Aug 2022 10:52:21 GMT'
    'x-ms-creation-time': 'REDACTED'
    'content-length': '121'
    'content-type': 'application/octet-stream'
    'content-range': 'REDACTED'
    'etag': '"0x23F1848F6690920"'
    'content-md5': 'REDACTED'
    'x-ms-blob-type': 'REDACTED'
    'x-ms-lease-state': 'REDACTED'
    'x-ms-lease-status': 'REDACTED'
    'x-ms-client-request-id': '8170fafe-1263-11ed-96b6-0242ac120007'
    'x-ms-request-id': '0b8f491d-760c-4425-894b-be658114bf1d'
    'x-ms-version': 'REDACTED'
    'accept-ranges': 'REDACTED'
    'date': 'Tue, 02 Aug 2022 13:03:30 GMT'
    'x-ms-server-encrypted': 'REDACTED'
    'x-ms-blob-content-md5': 'REDACTED'
    'Connection': 'keep-alive'
    'Keep-Alive': 'REDACTED'
[2022-08-02 13:03:30,157] {taskinstance.py:1909} ERROR - Task failed with exception
Traceback (most recent call last):
  File "/home/airflow/.local/lib/python3.7/site-packages/airflow/operators/python.py", line 171, in execute
    return_value = self.execute_callable()
  File "/home/airflow/.local/lib/python3.7/site-packages/airflow/operators/python.py", line 189, in execute_callable
    return self.python_callable(*self.op_args, **self.op_kwargs)
  File "/opt/airflow/dags/demo.py", line 69, in upload_data_mongodb
    file_json=json.loads(file)
  File "/usr/local/lib/python3.7/json/__init__.py", line 348, in loads
    return _default_decoder.decode(s)
  File "/usr/local/lib/python3.7/json/decoder.py", line 337, in decode
    obj, end = self.raw_decode(s, idx=_w(s, 0).end())
  File "/usr/local/lib/python3.7/json/decoder.py", line 355, in raw_decode
    raise JSONDecodeError("Expecting value", s, err.value) from None
json.decoder.JSONDecodeError: Expecting value: line 1 column 1 (char 0)
[2022-08-02 13:03:30,171] {taskinstance.py:1420} INFO - Marking task as FAILED. dag_id=Demo, task_id=data_uploading_mongodb, execution_date=20220802T130308, start_date=20220802T130329, end_date=20220802T130330
[2022-08-02 13:03:30,187] {standard_task_runner.py:97} ERROR - Failed to execute job 297 for task data_uploading_mongodb (Expecting value: line 1 column 1 (char 0); 10587)
[2022-08-02 13:03:30,214] {local_task_job.py:156} INFO - Task exited with return code 1
[2022-08-02 13:03:30,255] {local_task_job.py:273} INFO - 0 downstream tasks scheduled from follow-on schedule check
