[2022-08-01 15:40:24,626] {taskinstance.py:1179} INFO - Dependencies all met for <TaskInstance: Demo.data_fetching manual__2022-08-01T15:40:13.180557+00:00 [queued]>
[2022-08-01 15:40:24,638] {taskinstance.py:1179} INFO - Dependencies all met for <TaskInstance: Demo.data_fetching manual__2022-08-01T15:40:13.180557+00:00 [queued]>
[2022-08-01 15:40:24,638] {taskinstance.py:1376} INFO - 
--------------------------------------------------------------------------------
[2022-08-01 15:40:24,639] {taskinstance.py:1377} INFO - Starting attempt 1 of 1
[2022-08-01 15:40:24,639] {taskinstance.py:1378} INFO - 
--------------------------------------------------------------------------------
[2022-08-01 15:40:24,659] {taskinstance.py:1397} INFO - Executing <Task(PythonOperator): data_fetching> on 2022-08-01 15:40:13.180557+00:00
[2022-08-01 15:40:24,663] {standard_task_runner.py:52} INFO - Started process 174 to run task
[2022-08-01 15:40:24,667] {standard_task_runner.py:79} INFO - Running: ['***', 'tasks', 'run', 'Demo', 'data_fetching', 'manual__2022-08-01T15:40:13.180557+00:00', '--job-id', '125', '--raw', '--subdir', 'DAGS_FOLDER/demo.py', '--cfg-path', '/tmp/tmpzsv42vp4', '--error-file', '/tmp/tmpgldabcje']
[2022-08-01 15:40:24,667] {standard_task_runner.py:80} INFO - Job 125: Subtask data_fetching
[2022-08-01 15:40:24,744] {task_command.py:371} INFO - Running <TaskInstance: Demo.data_fetching manual__2022-08-01T15:40:13.180557+00:00 [running]> on host 31353b71d6cb
[2022-08-01 15:40:24,830] {taskinstance.py:1591} INFO - Exporting the following env vars:
AIRFLOW_CTX_DAG_OWNER=***
AIRFLOW_CTX_DAG_ID=Demo
AIRFLOW_CTX_TASK_ID=data_fetching
AIRFLOW_CTX_EXECUTION_DATE=2022-08-01T15:40:13.180557+00:00
AIRFLOW_CTX_TRY_NUMBER=1
AIRFLOW_CTX_DAG_RUN_ID=manual__2022-08-01T15:40:13.180557+00:00
[2022-08-01 15:40:24,842] {base.py:68} INFO - Using connection ID 'azure_demo' for task execution.
[2022-08-01 15:40:24,847] {_universal.py:476} INFO - Request URL: 'http://azurite:10000/devstoreaccount1/waves?restype=REDACTED&comp=REDACTED&delimiter=REDACTED'
Request method: 'GET'
Request headers:
    'x-ms-version': 'REDACTED'
    'Accept': 'application/xml'
    'User-Agent': 'azsdk-python-storage-blob/12.8.1 Python/3.7.13 (Linux-5.10.16.3-microsoft-standard-WSL2-x86_64-with-debian-11.4)'
    'x-ms-date': 'REDACTED'
    'x-ms-client-request-id': '42a6403a-11b0-11ed-bda0-0242ac120008'
    'Authorization': 'REDACTED'
No body was attached to the request
[2022-08-01 15:40:24,856] {_universal.py:504} INFO - Response status: 404
Response headers:
    'Server': 'Azurite-Blob/3.18.0'
    'x-ms-error-code': 'REDACTED'
    'x-ms-request-id': 'db2ee1d6-9b88-43e3-830a-fc192746d568'
    'content-type': 'application/xml'
    'Date': 'Mon, 01 Aug 2022 15:40:24 GMT'
    'Connection': 'keep-alive'
    'Keep-Alive': 'REDACTED'
    'Transfer-Encoding': 'chunked'
[2022-08-01 15:40:24,859] {taskinstance.py:1909} ERROR - Task failed with exception
Traceback (most recent call last):
  File "/home/airflow/.local/lib/python3.7/site-packages/azure/storage/blob/_list_blobs_helper.py", line 77, in _get_next_cb
    use_location=self.location_mode)
  File "/home/airflow/.local/lib/python3.7/site-packages/azure/storage/blob/_generated/operations/_container_operations.py", line 1576, in list_blob_hierarchy_segment
    map_error(status_code=response.status_code, response=response, error_map=error_map)
  File "/home/airflow/.local/lib/python3.7/site-packages/azure/core/exceptions.py", line 107, in map_error
    raise error
azure.core.exceptions.ResourceNotFoundError: Operation returned an invalid status 'The specified container does not exist.'
Content: <?xml version="1.0" encoding="UTF-8" standalone="yes"?>
<Error>
  <Code>ContainerNotFound</Code>
  <Message>The specified container does not exist.
RequestId:db2ee1d6-9b88-43e3-830a-fc192746d568
Time:2022-08-01T15:40:24.854Z</Message>
</Error>

During handling of the above exception, another exception occurred:

Traceback (most recent call last):
  File "/home/airflow/.local/lib/python3.7/site-packages/airflow/operators/python.py", line 171, in execute
    return_value = self.execute_callable()
  File "/home/airflow/.local/lib/python3.7/site-packages/airflow/operators/python.py", line 189, in execute_callable
    return self.python_callable(*self.op_args, **self.op_kwargs)
  File "/opt/airflow/dags/demo.py", line 36, in fetch_data
    x=test.get_blobs_list(container_name="waves")
  File "/home/airflow/.local/lib/python3.7/site-packages/airflow/providers/microsoft/azure/hooks/wasb.py", line 233, in get_blobs_list
    for blob in blobs:
  File "/home/airflow/.local/lib/python3.7/site-packages/azure/core/paging.py", line 128, in __next__
    return next(self._page_iterator)
  File "/home/airflow/.local/lib/python3.7/site-packages/azure/core/paging.py", line 76, in __next__
    self._response = self._get_next(self.continuation_token)
  File "/home/airflow/.local/lib/python3.7/site-packages/azure/storage/blob/_list_blobs_helper.py", line 79, in _get_next_cb
    process_storage_error(error)
  File "/home/airflow/.local/lib/python3.7/site-packages/azure/storage/blob/_shared/response_handlers.py", line 150, in process_storage_error
    error.raise_with_traceback()
  File "/home/airflow/.local/lib/python3.7/site-packages/azure/core/exceptions.py", line 249, in raise_with_traceback
    raise super(AzureError, self).with_traceback(self.exc_traceback)
  File "/home/airflow/.local/lib/python3.7/site-packages/azure/storage/blob/_list_blobs_helper.py", line 77, in _get_next_cb
    use_location=self.location_mode)
  File "/home/airflow/.local/lib/python3.7/site-packages/azure/storage/blob/_generated/operations/_container_operations.py", line 1576, in list_blob_hierarchy_segment
    map_error(status_code=response.status_code, response=response, error_map=error_map)
  File "/home/airflow/.local/lib/python3.7/site-packages/azure/core/exceptions.py", line 107, in map_error
    raise error
azure.core.exceptions.ResourceNotFoundError: The specified container does not exist.
RequestId:db2ee1d6-9b88-43e3-830a-fc192746d568
Time:2022-08-01T15:40:24.854Z
ErrorCode:ContainerNotFound
Error:
  
Content: <?xml version="1.0" encoding="UTF-8" standalone="yes"?>
<Error>
  <Code>ContainerNotFound</Code>
  <Message>The specified container does not exist.
RequestId:db2ee1d6-9b88-43e3-830a-fc192746d568
Time:2022-08-01T15:40:24.854Z</Message>
</Error>
[2022-08-01 15:40:24,874] {taskinstance.py:1420} INFO - Marking task as FAILED. dag_id=Demo, task_id=data_fetching, execution_date=20220801T154013, start_date=20220801T154024, end_date=20220801T154024
[2022-08-01 15:40:24,889] {standard_task_runner.py:97} ERROR - Failed to execute job 125 for task data_fetching (The specified container does not exist.
RequestId:db2ee1d6-9b88-43e3-830a-fc192746d568
Time:2022-08-01T15:40:24.854Z
ErrorCode:ContainerNotFound
Error:
  
Content: <?xml version="1.0" encoding="UTF-8" standalone="yes"?>
<Error>
  <Code>ContainerNotFound</Code>
  <Message>The specified container does not exist.
RequestId:db2ee1d6-9b88-43e3-830a-fc192746d568
Time:2022-08-01T15:40:24.854Z</Message>
</Error>; 174)
[2022-08-01 15:40:24,919] {local_task_job.py:156} INFO - Task exited with return code 1
[2022-08-01 15:40:24,972] {local_task_job.py:273} INFO - 0 downstream tasks scheduled from follow-on schedule check
