[2022-08-02 07:55:04,569] {taskinstance.py:1179} INFO - Dependencies all met for <TaskInstance: Demo.data_uploading manual__2022-08-02T07:54:55.704361+00:00 [queued]>
[2022-08-02 07:55:04,581] {taskinstance.py:1179} INFO - Dependencies all met for <TaskInstance: Demo.data_uploading manual__2022-08-02T07:54:55.704361+00:00 [queued]>
[2022-08-02 07:55:04,581] {taskinstance.py:1376} INFO - 
--------------------------------------------------------------------------------
[2022-08-02 07:55:04,581] {taskinstance.py:1377} INFO - Starting attempt 1 of 1
[2022-08-02 07:55:04,582] {taskinstance.py:1378} INFO - 
--------------------------------------------------------------------------------
[2022-08-02 07:55:04,602] {taskinstance.py:1397} INFO - Executing <Task(PythonOperator): data_uploading> on 2022-08-02 07:54:55.704361+00:00
[2022-08-02 07:55:04,606] {standard_task_runner.py:52} INFO - Started process 452 to run task
[2022-08-02 07:55:04,611] {standard_task_runner.py:79} INFO - Running: ['***', 'tasks', 'run', 'Demo', 'data_uploading', 'manual__2022-08-02T07:54:55.704361+00:00', '--job-id', '145', '--raw', '--subdir', 'DAGS_FOLDER/demo.py', '--cfg-path', '/tmp/tmpplaon7nt', '--error-file', '/tmp/tmpl8aia8j_']
[2022-08-02 07:55:04,612] {standard_task_runner.py:80} INFO - Job 145: Subtask data_uploading
[2022-08-02 07:55:04,698] {task_command.py:371} INFO - Running <TaskInstance: Demo.data_uploading manual__2022-08-02T07:54:55.704361+00:00 [running]> on host 31353b71d6cb
[2022-08-02 07:55:04,803] {taskinstance.py:1591} INFO - Exporting the following env vars:
AIRFLOW_CTX_DAG_OWNER=***
AIRFLOW_CTX_DAG_ID=Demo
AIRFLOW_CTX_TASK_ID=data_uploading
AIRFLOW_CTX_EXECUTION_DATE=2022-08-02T07:54:55.704361+00:00
AIRFLOW_CTX_TRY_NUMBER=1
AIRFLOW_CTX_DAG_RUN_ID=manual__2022-08-02T07:54:55.704361+00:00
[2022-08-02 07:55:04,814] {base.py:68} INFO - Using connection ID 'azure_demo' for task execution.
[2022-08-02 07:55:04,817] {logging_mixin.py:115} INFO - connection made successfully
[2022-08-02 07:55:04,819] {_universal.py:476} INFO - Request URL: 'http://127.0.0.1:10000/devstoreaccount1/waves?restype=REDACTED'
Request method: 'PUT'
Request headers:
    'x-ms-version': 'REDACTED'
    'Accept': 'application/xml'
    'User-Agent': 'azsdk-python-storage-blob/12.8.1 Python/3.7.13 (Linux-5.10.16.3-microsoft-standard-WSL2-x86_64-with-debian-11.4)'
    'x-ms-date': 'REDACTED'
    'x-ms-client-request-id': '6b6de9cc-1238-11ed-9218-0242ac120006'
    'Authorization': 'REDACTED'
No body was attached to the request
[2022-08-02 07:55:20,076] {_universal.py:476} INFO - Request URL: 'http://127.0.0.1:10000/devstoreaccount1/waves?restype=REDACTED'
Request method: 'PUT'
Request headers:
    'x-ms-version': 'REDACTED'
    'Accept': 'application/xml'
    'User-Agent': 'azsdk-python-storage-blob/12.8.1 Python/3.7.13 (Linux-5.10.16.3-microsoft-standard-WSL2-x86_64-with-debian-11.4)'
    'x-ms-date': 'REDACTED'
    'x-ms-client-request-id': '7485faa4-1238-11ed-9218-0242ac120006'
    'Authorization': 'REDACTED'
No body was attached to the request
[2022-08-02 07:55:46,756] {_universal.py:476} INFO - Request URL: 'http://127.0.0.1:10000/devstoreaccount1/waves?restype=REDACTED'
Request method: 'PUT'
Request headers:
    'x-ms-version': 'REDACTED'
    'Accept': 'application/xml'
    'User-Agent': 'azsdk-python-storage-blob/12.8.1 Python/3.7.13 (Linux-5.10.16.3-microsoft-standard-WSL2-x86_64-with-debian-11.4)'
    'x-ms-date': 'REDACTED'
    'x-ms-client-request-id': '846cda82-1238-11ed-9218-0242ac120006'
    'Authorization': 'REDACTED'
No body was attached to the request
[2022-08-02 07:56:29,426] {_universal.py:476} INFO - Request URL: 'http://127.0.0.1:10000/devstoreaccount1/waves?restype=REDACTED'
Request method: 'PUT'
Request headers:
    'x-ms-version': 'REDACTED'
    'Accept': 'application/xml'
    'User-Agent': 'azsdk-python-storage-blob/12.8.1 Python/3.7.13 (Linux-5.10.16.3-microsoft-standard-WSL2-x86_64-with-debian-11.4)'
    'x-ms-date': 'REDACTED'
    'x-ms-client-request-id': '9ddbfd72-1238-11ed-9218-0242ac120006'
    'Authorization': 'REDACTED'
No body was attached to the request
[2022-08-02 07:56:29,430] {wasb.py:386} INFO - Error while attempting to create container 'waves': <urllib3.connection.HTTPConnection object at 0x7f097ff9a150>: Failed to establish a new connection: [Errno 111] Connection refused
[2022-08-02 07:56:29,431] {taskinstance.py:1909} ERROR - Task failed with exception
Traceback (most recent call last):
  File "/home/airflow/.local/lib/python3.7/site-packages/airflow/operators/python.py", line 171, in execute
    return_value = self.execute_callable()
  File "/home/airflow/.local/lib/python3.7/site-packages/airflow/operators/python.py", line 189, in execute_callable
    return self.python_callable(*self.op_args, **self.op_kwargs)
  File "/opt/airflow/dags/demo.py", line 25, in upload_data
    test.create_container(container_name="waves")
  File "/home/airflow/.local/lib/python3.7/site-packages/airflow/providers/microsoft/azure/hooks/wasb.py", line 367, in create_container
    container_client.create_container()
  File "/home/airflow/.local/lib/python3.7/site-packages/azure/core/tracing/decorator.py", line 78, in wrapper_use_tracer
    return func(*args, **kwargs)
  File "/home/airflow/.local/lib/python3.7/site-packages/azure/storage/blob/_container_client.py", line 298, in create_container
    **kwargs)
  File "/home/airflow/.local/lib/python3.7/site-packages/azure/storage/blob/_generated/operations/_container_operations.py", line 128, in create
    pipeline_response = self._client._pipeline.run(request, stream=False, **kwargs)
  File "/home/airflow/.local/lib/python3.7/site-packages/azure/core/pipeline/_base.py", line 211, in run
    return first_node.send(pipeline_request)  # type: ignore
  File "/home/airflow/.local/lib/python3.7/site-packages/azure/core/pipeline/_base.py", line 71, in send
    response = self.next.send(request)
  File "/home/airflow/.local/lib/python3.7/site-packages/azure/core/pipeline/_base.py", line 71, in send
    response = self.next.send(request)
  File "/home/airflow/.local/lib/python3.7/site-packages/azure/core/pipeline/_base.py", line 71, in send
    response = self.next.send(request)
  [Previous line repeated 2 more times]
  File "/home/airflow/.local/lib/python3.7/site-packages/azure/core/pipeline/policies/_redirect.py", line 158, in send
    response = self.next.send(request)
  File "/home/airflow/.local/lib/python3.7/site-packages/azure/core/pipeline/_base.py", line 71, in send
    response = self.next.send(request)
  File "/home/airflow/.local/lib/python3.7/site-packages/azure/storage/blob/_shared/policies.py", line 515, in send
    raise err
  File "/home/airflow/.local/lib/python3.7/site-packages/azure/storage/blob/_shared/policies.py", line 489, in send
    response = self.next.send(request)
  File "/home/airflow/.local/lib/python3.7/site-packages/azure/core/pipeline/_base.py", line 71, in send
    response = self.next.send(request)
  File "/home/airflow/.local/lib/python3.7/site-packages/azure/core/pipeline/_base.py", line 71, in send
    response = self.next.send(request)
  File "/home/airflow/.local/lib/python3.7/site-packages/azure/core/pipeline/_base.py", line 71, in send
    response = self.next.send(request)
  [Previous line repeated 1 more time]
  File "/home/airflow/.local/lib/python3.7/site-packages/azure/storage/blob/_shared/policies.py", line 290, in send
    response = self.next.send(request)
  File "/home/airflow/.local/lib/python3.7/site-packages/azure/core/pipeline/_base.py", line 71, in send
    response = self.next.send(request)
  File "/home/airflow/.local/lib/python3.7/site-packages/azure/core/pipeline/_base.py", line 71, in send
    response = self.next.send(request)
  File "/home/airflow/.local/lib/python3.7/site-packages/azure/core/pipeline/_base.py", line 103, in send
    self._sender.send(request.http_request, **request.context.options),
  File "/home/airflow/.local/lib/python3.7/site-packages/azure/storage/blob/_shared/base_client.py", line 333, in send
    return self._transport.send(request, **kwargs)
  File "/home/airflow/.local/lib/python3.7/site-packages/azure/core/pipeline/transport/_requests_basic.py", line 361, in send
    raise error
azure.core.exceptions.ServiceRequestError: <urllib3.connection.HTTPConnection object at 0x7f097ff9a150>: Failed to establish a new connection: [Errno 111] Connection refused
[2022-08-02 07:56:29,450] {taskinstance.py:1420} INFO - Marking task as FAILED. dag_id=Demo, task_id=data_uploading, execution_date=20220802T075455, start_date=20220802T075504, end_date=20220802T075629
[2022-08-02 07:56:29,468] {standard_task_runner.py:97} ERROR - Failed to execute job 145 for task data_uploading (<urllib3.connection.HTTPConnection object at 0x7f097ff9a150>: Failed to establish a new connection: [Errno 111] Connection refused; 452)
[2022-08-02 07:56:29,479] {local_task_job.py:156} INFO - Task exited with return code 1
[2022-08-02 07:56:29,533] {local_task_job.py:273} INFO - 0 downstream tasks scheduled from follow-on schedule check
