[2022-08-02 10:11:52,317] {taskinstance.py:1179} INFO - Dependencies all met for <TaskInstance: Demo.records_saving manual__2022-08-02T10:11:29.339839+00:00 [queued]>
[2022-08-02 10:11:52,383] {taskinstance.py:1179} INFO - Dependencies all met for <TaskInstance: Demo.records_saving manual__2022-08-02T10:11:29.339839+00:00 [queued]>
[2022-08-02 10:11:52,384] {taskinstance.py:1376} INFO - 
--------------------------------------------------------------------------------
[2022-08-02 10:11:52,386] {taskinstance.py:1377} INFO - Starting attempt 1 of 1
[2022-08-02 10:11:52,389] {taskinstance.py:1378} INFO - 
--------------------------------------------------------------------------------
[2022-08-02 10:11:52,475] {taskinstance.py:1397} INFO - Executing <Task(PythonOperator): records_saving> on 2022-08-02 10:11:29.339839+00:00
[2022-08-02 10:11:52,492] {standard_task_runner.py:52} INFO - Started process 4520 to run task
[2022-08-02 10:11:52,511] {standard_task_runner.py:79} INFO - Running: ['***', 'tasks', 'run', 'Demo', 'records_saving', 'manual__2022-08-02T10:11:29.339839+00:00', '--job-id', '211', '--raw', '--subdir', 'DAGS_FOLDER/demo.py', '--cfg-path', '/tmp/tmpzbxlj531', '--error-file', '/tmp/tmp24slhld5']
[2022-08-02 10:11:52,515] {standard_task_runner.py:80} INFO - Job 211: Subtask records_saving
[2022-08-02 10:11:52,846] {task_command.py:371} INFO - Running <TaskInstance: Demo.records_saving manual__2022-08-02T10:11:29.339839+00:00 [running]> on host 31353b71d6cb
[2022-08-02 10:11:53,031] {taskinstance.py:1591} INFO - Exporting the following env vars:
AIRFLOW_CTX_DAG_OWNER=***
AIRFLOW_CTX_DAG_ID=Demo
AIRFLOW_CTX_TASK_ID=records_saving
AIRFLOW_CTX_EXECUTION_DATE=2022-08-02T10:11:29.339839+00:00
AIRFLOW_CTX_TRY_NUMBER=1
AIRFLOW_CTX_DAG_RUN_ID=manual__2022-08-02T10:11:29.339839+00:00
[2022-08-02 10:11:53,053] {base.py:68} INFO - Using connection ID 'postgres_demo' for task execution.
[2022-08-02 10:11:53,062] {dbapi.py:231} INFO - Running statement: CREATE TABLE IF NOT EXISTS public."Files"
                            (
                                id integer NOT NULL,
                                name character(80)[] COLLATE pg_catalog."default" NOT NULL,
                                size bigint,
                                CONSTRAINT "Files_pkey" PRIMARY KEY (id)
                            ), parameters: None
[2022-08-02 10:11:53,080] {base.py:68} INFO - Using connection ID 'postgres_demo' for task execution.
[2022-08-02 10:11:53,087] {dbapi.py:231} INFO - Running statement: INSERT INTO public."Files"(
                                id, name, size)
                                VALUES (%(parameters.id)s, %(parameters.name)s, %(parameters.size)s);, parameters: {'id': 0, 'name': 'houssem', 'size': 100}
[2022-08-02 10:11:53,089] {taskinstance.py:1909} ERROR - Task failed with exception
Traceback (most recent call last):
  File "/home/airflow/.local/lib/python3.7/site-packages/airflow/operators/python.py", line 171, in execute
    return_value = self.execute_callable()
  File "/home/airflow/.local/lib/python3.7/site-packages/airflow/operators/python.py", line 189, in execute_callable
    return self.python_callable(*self.op_args, **self.op_kwargs)
  File "/opt/airflow/dags/demo.py", line 62, in save_records
    VALUES (%(parameters.id)s, %(parameters.name)s, %(parameters.size)s);""",parameters={"id":i,"name":"houssem","size":i+100})
  File "/home/airflow/.local/lib/python3.7/site-packages/airflow/hooks/dbapi.py", line 211, in run
    self._run_command(cur, sql_statement, parameters)
  File "/home/airflow/.local/lib/python3.7/site-packages/airflow/hooks/dbapi.py", line 233, in _run_command
    cur.execute(sql_statement, parameters)
KeyError: 'parameters.id'
[2022-08-02 10:11:53,121] {taskinstance.py:1420} INFO - Marking task as FAILED. dag_id=Demo, task_id=records_saving, execution_date=20220802T101129, start_date=20220802T101152, end_date=20220802T101153
[2022-08-02 10:11:53,150] {standard_task_runner.py:97} ERROR - Failed to execute job 211 for task records_saving ('parameters.id'; 4520)
[2022-08-02 10:11:53,202] {local_task_job.py:156} INFO - Task exited with return code 1
[2022-08-02 10:11:53,468] {local_task_job.py:273} INFO - 0 downstream tasks scheduled from follow-on schedule check
